<?xml version="1.0"?>
<robot name="group19Bot" xmlns:xacro="https://www.ros.org/wiki/xacro" >
    
    <!-- Create a robot chassis as Base Link -->
    <link name="base_link">
		  <visual>
		    <origin rpy="0 0 0" xyz="0 0 0"/>
		    <geometry>
		      <box size="0.5 0.3 0.07"/>
		    </geometry>
		    <material name="grey">
          <color rgba="0.5 0.5 0.5 1.0"/>
        </material>
		  </visual>
      <!-- Base pose, collision and inertial -->
      <pose>0 0 0.1 0 0 0</pose>
      <collision>
        <geometry>
          <box size="0.5 0.3 0.07"/>
        </geometry>
      </collision>
      <inertial>
        <mass value="5"/>
        <origin rpy="0 0 0" xyz="0 0 0.1"/>
        <inertia ixx="0.03954" ixy="0" ixz="0" iyy="0.10621" iyz="0" izz="0.10621"/>
      </inertial>
     
      <!-- caster -->
      <visual name="caster">
        <origin rpy=" 0 0 0" xyz="0.2 0 -0.05"/>
        <geometry>
          <sphere radius="0.05"/>
        </geometry>
        <material name="black">
          <color rgba="0.05 0.05 0.05 1.0"/>
        </material>
      </visual>
      <!-- Caster collision and inertial -->
      <collision>
        <origin xyz="0.35 0 -0.05" rpy="0 0 0" />
        <geometry>
          <sphere radius="0.05" />
        </geometry>
      </collision>
      <inertial>
        <mass value="0.5"/>
        <inertia ixx="0.0005" ixy="0.0" ixz="0.0" iyy="0.0005" iyz="0.0" izz="0.0005"/>
      </inertial>    
    </link>
  
  <!-- Create wheel right -->  
     <link name="right_wheel">      
        <visual>
          <origin rpy="0 1.5707 1.5707" xyz="0 0 0"/>
          <geometry>
            <cylinder length="0.04" radius="0.1"/>
          </geometry>      
        </visual>
        <!--right wheel collision and inertial-->  
        <collision>
          <origin rpy="0 1.5707 1.5707" xyz="0 0 0" />
          <geometry>
            <cylinder length="0.04" radius="0.1"/>
          </geometry>
        </collision>
        <inertial>
          <mass value="0.2"/>
          <origin rpy="0 1.5707 1.5707" xyz="0 0 0"/>
          <inertia ixx="0.000527" ixy="0" ixz="0" iyy="0.000527" iyz="0" izz="0.001"/>
        </inertial>  
    </link>
    
    <!--   Joint for right wheel  -->
    <joint name="joint_right_wheel" type="continuous">
      <origin rpy="0 0 0" xyz="-0.05 0.15 0"/>
      <child link="right_wheel"/>
      <parent link="base_link"/>
      <axis rpy="0 0 0" xyz="0 1 0"/>
      <limit effort="10000" velocity="1000"/>
      <dynamics damping="1.0" friction="1.0" />
    </joint>  
    
    <!-- Left Wheel link -->   
    <link name="left_wheel">    
      <visual>
        <origin rpy="0 1.5706 1.5707" xyz="0 0 0"/>
        <geometry>
          <cylinder length="0.04" radius="0.1"/>
        </geometry>      
      </visual> 
      <!--left wheel collision and inertial-->
      <collision>
        <origin rpy="0 1.5707 1.5707" xyz="0 0 0" />
        <geometry>
          <cylinder length="0.04" radius="0.1"/>
        </geometry>
      </collision>
      <inertial>
        <mass value="0.2"/>
        <origin rpy="0 1.5707 1.5707" xyz="0 0 0"/>
        <inertia ixx="0.000527" ixy="0" ixz="0" iyy="0.000527" iyz="0" izz="0.001"/>
      </inertial>      
      
    </link>

    <!-- Add a laser scan sensor cylindrical in shape to our robots urdf model-->
    <!-- first create a link representing the sensor-->
     <link name="laser_sensor">
      <visual>
        <origin xyz="0 0 0" rpy="0 0 0" />
        <geometry>
          <cylinder radius="0.05" length="0.1"/>
        </geometry>
        <material name="grey">
          <color rgba="1.0 1.0 1.0 1.0"/>
        </material>
      </visual>

      <collision>
        <origin xyz="0 0 0" rpy="0 0 0"/>
        <geometry>
          <cylinder radius="0.05" length="0.1"/>
        </geometry>
      </collision>

      <inertial>
        <origin xyz="0 0 0" rpy="0 0 0" />
        <mass value="1" />
        <inertia ixx="0.0015" ixy="0" ixz="0" iyy="0.0015" iyz="0" izz="0.0012"/>
      </inertial> 
    </link>

    <!--Add a joint element to our robot. This will connect the sensor to robot body rigidly.-->
     <joint name="joint_sensor_laser" type="fixed">
        <origin xyz="0.15 0 0.05" rpy="0 0 0"/>
        <parent link="base_link"/>
        <child link="laser_sensor"/>
     </joint>

    
    <!--   Joint for left wheel  -->
    <joint name="joint_left_wheel" type="continuous">
      <origin rpy="0 0 0" xyz="-0.05 -0.15 0"/>
      <child link="left_wheel"/>
      <parent link="base_link"/>
      <axis rpy="0 0 0" xyz="0 1 0"/>
      <limit effort="10000" velocity="1000"/>
      <dynamics damping="1.0" friction="1.0" />
    </joint>

    <!--To add the sensor beharior to the link, we use the laser gazebo plugin-->
    <gazebo reference="laser_sensor">
      <sensor type="ray" name="head_hokuyo_sensor">
        <pose>0 0 0 0 0 0</pose>
        <visualize>true</visualize>
        <update_rate>20</update_rate> <!--Update rate : Controls how often (how fast) the laser data is captured-->
        <ray>
          <scan>
            <horizontal>
              <samples>720</samples><!--samples : Defines how how many readings are contained in one scan-->
              <resolution>1</resolution><!--resolution : Defines the minimum angular distance between readings captured in a laser scan-->
              <min_angle>-1.570796</min_angle>
              <max_angle>1.570796</max_angle>
            </horizontal>
          </scan>
          <range><!--range : Defines the minimum sense distance and maximum sense distance-->
            <min>0.10</min>
            <max>10.0</max>
            <resolution>0.01</resolution><!--It defines the minimum distance between 2 points such that two points can be resolved as two separate points.-->
          </range>
          <noise><!--noise : This parameter lets us add gaussian noise to the range data captured by the sensor-->
            <type>gaussian</type>
            <mean>0.0</mean>
            <stddev>0.01</stddev>
          </noise>
        </ray>
        <plugin name="gazebo_ros_head_hokuyo_controller" filename="libgazebo_ros_laser.so">
          <topicName>/group19Bot/laser/scan</topicName><!--topicName : Defines the name which is used for publishing the laser data-->
          <frameName>laser_sensor</frameName><!--frameName : Defines the link to which the plugin has to be applied-->
        </plugin>
      </sensor>
    </gazebo>

    <!--specifying color in Gazebo-->
    <gazebo reference="base_link">
	    <material>Gazebo/Grey</material>
    </gazebo>
    <gazebo reference="left_wheel">
	    <material>Gazebo/Black</material>
    </gazebo>
    <gazebo reference="right_wheel">
	    <material>Gazebo/Black</material>
    </gazebo>

    <!--adding a differential drive plugin-->
    <gazebo>
      <plugin filename="libgazebo_ros_diff_drive.so" name="differential_drive_controller">
        <alwaysOn>true</alwaysOn>
        <updateRate>20</updateRate>
        <leftJoint>joint_left_wheel</leftJoint>
        <rightJoint>joint_right_wheel</rightJoint>
        <wheelSeparation>0.4</wheelSeparation>
        <wheelDiameter>0.2</wheelDiameter>
        <torque>0.1</torque>
        <commandTopic>group19Bot/cmd_vel</commandTopic>
        <odometryTopic>odom</odometryTopic>
        <odometryFrame>odom</odometryFrame>
        <robotBaseFrame>base_link</robotBaseFrame>
        <publishWheelJointState>true</publishWheelJointState>
        <legacyMode>true</legacyMode>
        <wheelAcceleration>0</wheelAcceleration>
        <publishOdomTF>true</publishOdomTF>
        <publishWheelTF>false</publishWheelTF>
        <wheelTorque>5</wheelTorque>
        <odometrySource>world</odometrySource>
        <publishTf>1</publishTf>
        <rosDebugLevel>info</rosDebugLevel>
      </plugin>
    </gazebo>
</robot>
